Workbook

Sheet Summary
A1: ESPMO Portfolio Intake — Defensible Guessed Tier Split v01.3
A2: Scoring basis (Profiler-faithful): VC = round(Total Value − (avg(business, technical complexity) × 2.5)). Full if VC ≥ 80. Mini if Value < 60 AND avg complexity < 2.5. Otherwise Standard.
A4: Tier | B4: Count | C4: Share of Active | D4: Governance interpretation
A5: Mini | B5: =COUNTIF('Defensible Tiering'!$J$2:$J$50,"Mini") -> 10 | C5: =B5/$B$9 -> 0.20833333 | D5: Lightweight / mini governance: only allowed when value is below 60 and complexity is 2.5 or lower.
A6: Standard | B6: =COUNTIF('Defensible Tiering'!$J$2:$J$50,"Standard") -> 25 | C6: =B6/$B$9 -> 0.52083333 | D6: Standard governance: not Full, and either value is 60+ or complexity is above the Mini gate.
A7: Full | B7: =COUNTIF('Defensible Tiering'!$J$2:$J$50,"Full") -> 13 | C7: =B7/$B$9 -> 0.27083333 | D7: Full governance plan required: estimated VC score is greater than 79.
A8: Not Tiered | B8: =COUNTIF('Defensible Tiering'!$J$2:$J$50,"Not Tiered") -> 1 | D8: Cancelled / inactive / excluded from active tier split.
A9: Active total | B9: =B10-B8 -> 48 | D9: Total rows minus Not Tiered.
A10: Portfolio rows | B10: =COUNTA('Defensible Tiering'!$B$2:$B$50) -> 49 | D10: All rows in the uploaded intake index.
A13: Rule Guardrail | B13: Result | C13: Pass target
A14: Mini rows with Value ≥ 60 | B14: =COUNTIFS('Defensible Tiering'!$J$2:$J$50,"Mini",'Defensible Tiering'!$E$2:$E$50,">=60") -> 0 | C14: 0
A15: Mini rows with Complexity > 2.5 | B15: =COUNTIFS('Defensible Tiering'!$J$2:$J$50,"Mini",'Defensible Tiering'!$G$2:$G$50,">2.5") -> 0 | C15: 0
A16: Full rows with VC < 80 | B16: =COUNTIFS('Defensible Tiering'!$J$2:$J$50,"Full",'Defensible Tiering'!$I$2:$I$50,"<80") -> 0 | C16: 0

Sheet Defensible Tiering
A1: Priority | B1: Project Name | C1: Project Manager | D1: Score Status | E1: Estimated Value | F1: Why Value Score | G1: Estimated Avg Complexity | H1: Why Complexity Score | I1: Estimated VC | J1: Guessed Tier | K1: Tier Rule / Why | L1: Confidence | M1: Type | N1: Phase | O1: Customer | P1: Security Status | Q1: ITB Division | R1: Notes
A2: 1.1 | B2: ICMS (Integrated Claims Management System) | C2: Mankin-Guiney, Christy | D2: Active | E2: 100 | F2: Priority 1.1 plus integrated claims management / core benefit platform signal. | G2: 3.4 | H2: Integrated claims platform with modernization-level system and cybersecurity coordination. | I2: =ROUND(E2-(G2*2.5),0) -> 92 | J2: =IF(D2<>"Active","Not Tiered",IF(I2>=80,"Full",IF(AND(E2<60,G2<2.5),"Mini","Standard"))) -> Full | K2: =IF(D2<>"Active","Cancelled/inactive; excluded from active governance tier counts.",IF(J2="Full","Profiler band: VC "&TEXT(I2,"0")&" >= 80, so Full governance plan is required.",IF(J2="Mini","Profiler band: Value "&TEXT(E2,"0")&" < 60 and avg complexity "&TEXT(G2,"0.0")&" < 2.5, so Mini is allowed.","Profiler band: VC "&TEXT(I2,"0")&" < 80 and Mini gate not met ("&IF(E2>=60,"value >= 60","avg complexity >= 2.5")&"), so Standard."))) -> Profiler band: VC 92 >= 80, so Full governance plan is required. | L2: High | M2: Project | N2: Planning | O2: ITB | P2: Not Submitted | Q2: EDDNext | R2: Project is in planning phase, Cybersecurity team engaged
A3: 1.2 | B3: SDIOe BPR / Plain Language R2 | C3: Madan, Supreet | D3: Active | E3: 100 | F3: Priority 1.2 and plain-language/BPR scope tied to high customer and operational value. | G3: 2.7 | H3: Business-process redesign/release work; meaningful workflow impact but not a full platform replacement. | I3: =ROUND(E3-(G3*2.5),0) -> 93 | J3: =IF(D3<>"Active","Not Tiered",IF(I3>=80,"Full",IF(AND(E3<60,G3<2.5),"Mini","Standard"))) -> Full | K3: =IF(D3<>"Active","Cancelled/inactive; excluded from active governance tier counts.",IF(J3="Full","Profiler band: VC "&TEXT(I3,"0")&" >= 80, so Full governance plan is required.",IF(J3="Mini","Profiler band: Value "&TEXT(E3,"0")&" < 60 and avg complexity "&TEXT(G3,"0.0")&" < 2.5, so Mini is allowed.","Profiler band: VC "&TEXT(I3,"0")&" < 80 and Mini gate not met ("&IF(E3>=60,"value >= 60","avg complexity >= 2.5")&"), so Standard."))) -> Profiler band: VC 93 >= 80, so Full governance plan is required. | L3: High | M3: Project | N3: Execution | O3: ITB | P3: Not Submitted | Q3: EDDNext
A4: 1.3 | B4: Integrated Contact Center | C4: Dahyia, Sarabjit | D4: Active | E4: 100 | F4: Priority 1.3 and contact-center scope suggests enterprise customer-service value. | G4: 3.4 | H4: Integrated contact-center implementation with updated comprehensive project plan and multi-team coordination. | I4: =ROUND(E4-(G4*2.5),0) -> 92 | J4: =IF(D4<>"Active","Not Tiered",IF(I4>=80,"Full",IF(AND(E4<60,G4<2.5),"Mini","Standard"))) -> Full | K4: =IF(D4<>"Active","Cancelled/inactive; excluded from active governance tier counts.",IF(J4="Full","Profiler band: VC "&TEXT(I4,"0")&" >= 80, so Full governance plan is required.",IF(J4="Mini","Profiler band: Value "&TEXT(E4,"0")&" < 60 and avg complexity "&TEXT(G4,"0.0")&" < 2.5, so Mini is allowed.","Profiler band: VC "&TEXT(I4,"0")&" < 80 and Mini gate not met ("&IF(E4>=60,"value >= 60","avg complexity >= 2.5")&"), so Standard."))) -> Profiler band: VC 92 >= 80, so Full governance plan is required. | L4: High | M4: Project | N4: Execution | O4: ITB | P4: Submitted | Q4: PDD | R4: New PM's updating the project plan to be more comprehensive
A5: 1.4 | B5: Fraud and Data Analytics - ID Proofing | C5: McLaughlin, LeAnne | D5: Active | E5: 100 | F5: Priority 1.4 plus fraud, data analytics, and identity-proofing indicate high program/risk value. | G5: 2.7 | H5: Data/identity proofing scope has moderate-to-high complexity, with governance/security implications. | I5: =ROUND(E5-(G5*2.5),0) -> 93 | J5: =IF(D5<>"Active","Not Tiered",IF(I5>=80,"Full",IF(AND(E5<60,G5<2.5),"Mini","Standard"))) -> Full | K5: =IF(D5<>"Active","Cancelled/inactive; excluded from active governance tier counts.",IF(J5="Full","Profiler band: VC "&TEXT(I5,"0")&" >= 80, so Full governance plan is required.",IF(J5="Mini","Profiler band: Value "&TEXT(E5,"0")&" < 60 and avg complexity "&TEXT(G5,"0.0")&" < 2.5, so Mini is allowed.","Profiler band: VC "&TEXT(I5,"0")&" < 80 and Mini gate not met ("&IF(E5>=60,"value >= 60","avg complexity >= 2.5")&"), so Standard."))) -> Profiler band: VC 93 >= 80, so Full governance plan is required. | L5: High | M5: Project | N5: Execution | O5: ITB | P5: Submitted | Q5: EDDNext | R5: Stakeholder Register within Charter
A6: 1.5 | B6: DMS Document Management System (Modernization) | C6: Bruderer, Brett | D6: Active | E6: 100 | F6: Priority 1.5 and explicit document-management modernization signal high enterprise value. | G6: 3.4 | H6: System modernization and document-management platform scope create high implementation complexity. | I6: =ROUND(E6-(G6*2.5),0) -> 92 | J6: =IF(D6<>"Active","Not Tiered",IF(I6>=80,"Full",IF(AND(E6<60,G6<2.5),"Mini","Standard"))) -> Full | K6: =IF(D6<>"Active","Cancelled/inactive; excluded from active governance tier counts.",IF(J6="Full","Profiler band: VC "&TEXT(I6,"0")&" >= 80, so Full governance plan is required.",IF(J6="Mini","Profiler band: Value "&TEXT(E6,"0")&" < 60 and avg complexity "&TEXT(G6,"0.0")&" < 2.5, so Mini is allowed.","Profiler band: VC "&TEXT(I6,"0")&" < 80 and Mini gate not met ("&IF(E6>=60,"value >= 60","avg complexity >= 2.5")&"), so Standard."))) -> Profiler band: VC 92 >= 80, so Full governance plan is required. | L6: High | M6: Project | N6: Execution | O6: ITB | P6: Submitted | Q6: PDD | R6: Part of Second Submissions
A7: 2 | B7: SB 1058 - DI Demographic Data | C7: Cervantes, Ricardo | D7: Active | E7: 93 | F7: Priority 2 and statutory/DI demographic-data scope suggest high compliance and business value. | G7: 2.7 | H7: Data/reporting and statutory implementation create moderate complexity. | I7: =ROUND(E7-(G7*2.5),0) -> 86 | J7: =IF(D7<>"Active","Not Tiered",IF(I7>=80,"Full",IF(AND(E7<60,G7<2.5),"Mini","Standard"))) -> Full | K7: =IF(D7<>"Active","Cancelled/inactive; excluded from active governance tier counts.",IF(J7="Full","Profiler band: VC "&TEXT(I7,"0")&" >= 80, so Full governance plan is required.",IF(J7="Mini","Profiler band: Value "&TEXT(E7,"0")&" < 60 and avg complexity "&TEXT(G7,"0.0")&" < 2.5, so Mini is allowed.","Profiler band: VC "&TEXT(I7,"0")&" < 80 and Mini gate not met ("&IF(E7>=60,"value >= 60","avg complexity >= 2.5")&"), so Standard."))) -> Profiler band: VC 86 >= 80, so Full governance plan is required. | L7: High | M7: Project | N7: Execution | O7: DIB | P7: In Progress | Q7: TGD | R7: Outstanding - There was not one when i took over this project.
A8: 3 | B8: PFL Claim Filing - Foster Child Youth | C8: Cervantes, Ricardo | D8: Active | E8: 88 | F8: Priority 3 and benefit-claim filing scope signal high claimant-service value. | G8: 2.7 | H8: Claim filing changes are cross-functional and moderately complex. | I8: =ROUND(E8-(G8*2.5),0) -> 81 | J8: =IF(D8<>"Active","Not Tiered",IF(I8>=80,"Full",IF(AND(E8<60,G8<2.5),"Mini","Standard"))) -> Full | K8: =IF(D8<>"Active","Cancelled/inactive; excluded from active governance tier counts.",IF(J8="Full","Profiler band: VC "&TEXT(I8,"0")&" >= 80, so Full governance plan is required.",IF(J8="Mini","Profiler band: Value "&TEXT(E8,"0")&" < 60 and avg complexity "&TEXT(G8,"0.0")&" < 2.5, so Mini is allowed.","Profiler band: VC "&TEXT(I8,"0")&" < 80 and Mini gate not met ("&IF(E8>=60,"value >= 60","avg complexity >= 2.5")&"), so Standard."))) -> Profiler band: VC 81 >= 80, so Full governance plan is required. | L8: Medium | M8: Project | N8: Execution | O8: DIB | P8: In Progress | Q8: TGD
A9: 4 | B9: AB 2123 Related Forms Update | C9: Cervantes, Ricardo | D9: Active | E9: 80 | F9: Priority 4 and AB-related forms update indicate meaningful compliance value, but bounded scope. | G9: 2 | H9: Forms update is a limited/moderate implementation compared with system modernization. | I9: =ROUND(E9-(G9*2.5),0) -> 75 | J9: =IF(D9<>"Active","Not Tiered",IF(I9>=80,"Full",IF(AND(E9<60,G9<2.5),"Mini","Standard"))) -> Standard | K9: =IF(D9<>"Active","Cancelled/inactive; excluded from active governance tier counts.",IF(J9="Full","Profiler band: VC "&TEXT(I9,"0")&" >= 80, so Full governance plan is required.",IF(J9="Mini","Profiler band: Value "&TEXT(E9,"0")&" < 60 and avg complexity "&TEXT(G9,"0.0")&" < 2.5, so Mini is allowed.","Profiler band: VC "&TEXT(I9,"0")&" < 80 and Mini gate not met ("&IF(E9>=60,"value >= 60","avg complexity >= 2.5")&"), so Standard."))) -> Profiler band: VC 75 < 80 and Mini gate not met (value >= 60), so Standard. | L9: Medium | M9: Project | N9: Execution | O9: ITB | P9: In Progress | Q9: TGD
A10: 5 | B10: Enterprise Scheduling & Queuing System (Qmatic) | C10: Lewis, Tara | D10: Active | E10: 94 | F10: Priority 5 plus enterprise scheduling/queueing indicates broad customer-service value. | G10: 2.7 | H10: Enterprise scheduling and queueing introduces workflow and integration complexity. | I10: =ROUND(E10-(G10*2.5),0) -> 87 | J10: =IF(D10<>"Active","Not Tiered",IF(I10>=80,"Full",IF(AND(E10<60,G10<2.5),"Mini","Standard"))) -> Full | K10: =IF(D10<>"Active","Cancelled/inactive; excluded from active governance tier counts.",IF(J10="Full","Profiler band: VC "&TEXT(I10,"0")&" >= 80, so Full governance plan is required.",IF(J10="Mini","Profiler band: Value "&TEXT(E10,"0")&" < 60 and avg complexity "&TEXT(G10,"0.0")&" < 2.5, so Mini is allowed.","Profiler band: VC "&TEXT(I10,"0")&" < 80 and Mini gate not met ("&IF(E10>=60,"value >= 60","avg complexity >= 2.5")&"), so Standard."))) -> Profiler band: VC 87 >= 80, so Full governance plan is required. | L10: High | M10: Project | N10: Execution | O10: DIB | P10: Submitted | Q10: TGD
A11: 6 | B11: CalJOBS Modernization Project | C11: Morales, Monica | D11: Active | E11: 96 | F11: Priority 6 and explicit CalJOBS modernization signal high statewide workforce-service value. | G11: 3.4 | H11: Major modernization with business, technical, and implementation complexity. | I11: =ROUND(E11-(G11*2.5),0) -> 88 | J11: =IF(D11<>"Active","Not Tiered",IF(I11>=80,"Full",IF(AND(E11<60,G11<2.5),"Mini","Standard"))) -> Full | K11: =IF(D11<>"Active","Cancelled/inactive; excluded from active governance tier counts.",IF(J11="Full","Profiler band: VC "&TEXT(I11,"0")&" >= 80, so Full governance plan is required.",IF(J11="Mini","Profiler band: Value "&TEXT(E11,"0")&" < 60 and avg complexity "&TEXT(G11,"0.0")&" < 2.5, so Mini is allowed.","Profiler band: VC "&TEXT(I11,"0")&" < 80 and Mini gate not met ("&IF(E11>=60,"value >= 60","avg complexity >= 2.5")&"), so Standard."))) -> Profiler band: VC 88 >= 80, so Full governance plan is required. | L11: High | M11: Project | N11: Execution | O11: WSB | P11: Not Submitted | Q11: TGD | R11: Second Submission
A12: 7 | B12: EDD LMI GenAI POC | C12: Cacal, Richilda Mae | D12: Active | E12: 58 | F12: POC language and no required security documentation indicate exploratory/limited value under governance scoring. | G12: 2 | H12: POC scope is intentionally bounded and low-to-moderate complexity. | I12: =ROUND(E12-(G12*2.5),0) -> 53 | J12: =IF(D12<>"Active","Not Tiered",IF(I12>=80,"Full",IF(AND(E12<60,G12<2.5),"Mini","Standard"))) -> Mini | K12: =IF(D12<>"Active","Cancelled/inactive; excluded from active governance tier counts.",IF(J12="Full","Profiler band: VC "&TEXT(I12,"0")&" >= 80, so Full governance plan is required.",IF(J12="Mini","Profiler band: Value "&TEXT(E12,"0")&" < 60 and avg complexity "&TEXT(G12,"0.0")&" < 2.5, so Mini is allowed.","Profiler band: VC "&TEXT(I12,"0")&" < 80 and Mini gate not met ("&IF(E12>=60,"value >= 60","avg complexity >= 2.5")&"), so Standard."))) -> Profiler band: Value 58 < 60 and avg complexity 2.0 < 2.5, so Mini is allowed. | L12: High | M12: Project | N12: Execution | O12: LDCB | P12: Not Submitted | Q12: TGD | R12: POC No Security documentation needed for effort
A13: 8 | B13: Direct Deposit Benefit Payments (SB 497/AB 138) | C13: Clark, Sabrina | D13: Active | E13: 95 | F13: Direct deposit benefit payments plus statute references signal high claimant/payment value despite Strike type. | G13: 3.3 | H13: Payment implementation across benefit programs is complex enough that Strike status should not make it Mini. | I13: =ROUND(E13-(G13*2.5),0) -> 87 | J13: =IF(D13<>"Active","Not Tiered",IF(I13>=80,"Full",IF(AND(E13<60,G13<2.5),"Mini","Standard"))) -> Full | K13: =IF(D13<>"Active","Cancelled/inactive; excluded from active governance tier counts.",IF(J13="Full","Profiler band: VC "&TEXT(I13,"0")&" >= 80, so Full governance plan is required.",IF(J13="Mini","Profiler band: Value "&TEXT(E13,"0")&" < 60 and avg complexity "&TEXT(G13,"0.0")&" < 2.5, so Mini is allowed.","Profiler band: VC "&TEXT(I13,"0")&" < 80 and Mini gate not met ("&IF(E13>=60,"value >= 60","avg complexity >= 2.5")&"), so Standard."))) -> Profiler band: VC 87 >= 80, so Full governance plan is required. | L13: High | M13: Strike | N13: Completed | O13: DIB/UIB | P13: Not Submitted | Q13: ASD | R13: Only tracked schedule, there is no folder to look at
A14: 9 | B14: Modernizing Employer Authentication | C14: Manandhar, Prabina | D14: Active | E14: 87 | F14: Employer authentication across WSB/UIB/TAX is high value, even though listed as Strike. | G14: 3.3 | H14: Identity/authentication across multiple branches is complex; Strike type does not override score thresholds. | I14: =ROUND(E14-(G14*2.5),0) -> 79 | J14: =IF(D14<>"Active","Not Tiered",IF(I14>=80,"Full",IF(AND(E14<60,G14<2.5),"Mini","Standard"))) -> Standard | K14: =IF(D14<>"Active","Cancelled/inactive; excluded from active governance tier counts.",IF(J14="Full","Profiler band: VC "&TEXT(I14,"0")&" >= 80, so Full governance plan is required.",IF(J14="Mini","Profiler band: Value "&TEXT(E14,"0")&" < 60 and avg complexity "&TEXT(G14,"0.0")&" < 2.5, so Mini is allowed.","Profiler band: VC "&TEXT(I14,"0")&" < 80 and Mini gate not met ("&IF(E14>=60,"value >= 60","avg complexity >= 2.5")&"), so Standard."))) -> Profiler band: VC 79 < 80 and Mini gate not met (value >= 60), so Standard. | L14: Medium | M14: Strike | N14: Execution | O14: WSB/UIB/TAX | P14: In Progress | Q14: PDD | R14: Strike effort and project team is working with Cybersecuritydocumentation is in progress
A15: 10 | B15: ServiceNow IT Asset Mgmt & Customer Service Mgmt | C15: Chandrapal, Deepak | D15: Active | E15: 90 | F15: ServiceNow ITAM/CSM impacts enterprise IT service management and customer-service operations. | G15: 3.4 | H15: Platform/module implementation and process change create high technical/operational complexity. | I15: =ROUND(E15-(G15*2.5),0) -> 82 | J15: =IF(D15<>"Active","Not Tiered",IF(I15>=80,"Full",IF(AND(E15<60,G15<2.5),"Mini","Standard"))) -> Full | K15: =IF(D15<>"Active","Cancelled/inactive; excluded from active governance tier counts.",IF(J15="Full","Profiler band: VC "&TEXT(I15,"0")&" >= 80, so Full governance plan is required.",IF(J15="Mini","Profiler band: Value "&TEXT(E15,"0")&" < 60 and avg complexity "&TEXT(G15,"0.0")&" < 2.5, so Mini is allowed.","Profiler band: VC "&TEXT(I15,"0")&" < 80 and Mini gate not met ("&IF(E15>=60,"value >= 60","avg complexity >= 2.5")&"), so Standard."))) -> Profiler band: VC 82 >= 80, so Full governance plan is required. | L15: Medium | M15: Project | N15: Execution | O15: ITB | P15: In Progress | Q15: TGD
A16: 11 | B16: AWS Q POC - UI Determination Quality | C16: Joji, Jerin | D16: Active | E16: 64 | F16: POC language lowers value, but UI determination quality and ITB involvement keep it above Mini. | G16: 2.3 | H16: POC remains bounded, but UI quality scope adds moderate business/technical complexity. | I16: =ROUND(E16-(G16*2.5),0) -> 58 | J16: =IF(D16<>"Active","Not Tiered",IF(I16>=80,"Full",IF(AND(E16<60,G16<2.5),"Mini","Standard"))) -> Standard | K16: =IF(D16<>"Active","Cancelled/inactive; excluded from active governance tier counts.",IF(J16="Full","Profiler band: VC "&TEXT(I16,"0")&" >= 80, so Full governance plan is required.",IF(J16="Mini","Profiler band: Value "&TEXT(E16,"0")&" < 60 and avg complexity "&TEXT(G16,"0.0")&" < 2.5, so Mini is allowed.","Profiler band: VC "&TEXT(I16,"0")&" < 80 and Mini gate not met ("&IF(E16>=60,"value >= 60","avg complexity >= 2.5")&"), so Standard."))) -> Profiler band: VC 58 < 80 and Mini gate not met (value >= 60), so Standard. | L16: Medium | M16: Project | N16: Execution | O16: UIB/ITB | P16: Not Submitted | Q16: TGD | R16: Starting Project
A17: 12 | B17: Snowflake Cloud Data Warehouse Implementation | C17: Mamidala, Srinivas | D17: Active | E17: 100 | F17: Cloud data warehouse implementation has enterprise data-platform value. | G17: 3.4 | H17: Cloud data warehouse implementation is a major technical/platform effort. | I17: =ROUND(E17-(G17*2.5),0) -> 92 | J17: =IF(D17<>"Active","Not Tiered",IF(I17>=80,"Full",IF(AND(E17<60,G17<2.5),"Mini","Standard"))) -> Full | K17: =IF(D17<>"Active","Cancelled/inactive; excluded from active governance tier counts.",IF(J17="Full","Profiler band: VC "&TEXT(I17,"0")&" >= 80, so Full governance plan is required.",IF(J17="Mini","Profiler band: Value "&TEXT(E17,"0")&" < 60 and avg complexity "&TEXT(G17,"0.0")&" < 2.5, so Mini is allowed.","Profiler band: VC "&TEXT(I17,"0")&" < 80 and Mini gate not met ("&IF(E17>=60,"value >= 60","avg complexity >= 2.5")&"), so Standard."))) -> Profiler band: VC 92 >= 80, so Full governance plan is required. | L17: High | M17: Project | N17: Execution | O17: ENT | P17: Submitted | Q17: EDDNext | R17: Tied to NLAB decisions
A18: 13 | B18: System Modifications to Comply with FEHA | C18: Hussaini, Parviz | D18: Active | E18: 87 | F18: FEHA compliance scope gives high statutory/risk value despite bounded implementation. | G18: 2 | H18: System modifications are scoped and lower complexity than modernization. | I18: =ROUND(E18-(G18*2.5),0) -> 82 | J18: =IF(D18<>"Active","Not Tiered",IF(I18>=80,"Full",IF(AND(E18<60,G18<2.5),"Mini","Standard"))) -> Full | K18: =IF(D18<>"Active","Cancelled/inactive; excluded from active governance tier counts.",IF(J18="Full","Profiler band: VC "&TEXT(I18,"0")&" >= 80, so Full governance plan is required.",IF(J18="Mini","Profiler band: Value "&TEXT(E18,"0")&" < 60 and avg complexity "&TEXT(G18,"0.0")&" < 2.5, so Mini is allowed.","Profiler band: VC "&TEXT(I18,"0")&" < 80 and Mini gate not met ("&IF(E18>=60,"value >= 60","avg complexity >= 2.5")&"), so Standard."))) -> Profiler band: VC 82 >= 80, so Full governance plan is required. | L18: High | M18: Project | N18: Execution | O18: ITB | P18: Submitted | Q18: TGD | R18: Security documentation not needed for this effort
A19: 14 | B19: EDDConnect Request for Personnel Action (RPA) | C19: Yang, Ming | D19: Active | E19: 55 | F19: Strike/enhancement to existing system with admin RPA scope stays below the Mini value ceiling. | G19: 1.7 | H19: Existing-system enhancement and admin workflow scope are low complexity. | I19: =ROUND(E19-(G19*2.5),0) -> 51 | J19: =IF(D19<>"Active","Not Tiered",IF(I19>=80,"Full",IF(AND(E19<60,G19<2.5),"Mini","Standard"))) -> Mini | K19: =IF(D19<>"Active","Cancelled/inactive; excluded from active governance tier counts.",IF(J19="Full","Profiler band: VC "&TEXT(I19,"0")&" >= 80, so Full governance plan is required.",IF(J19="Mini","Profiler band: Value "&TEXT(E19,"0")&" < 60 and avg complexity "&TEXT(G19,"0.0")&" < 2.5, so Mini is allowed.","Profiler band: VC "&TEXT(I19,"0")&" < 80 and Mini gate not met ("&IF(E19>=60,"value >= 60","avg complexity >= 2.5")&"), so Standard."))) -> Profiler band: Value 55 < 60 and avg complexity 1.7 < 2.5, so Mini is allowed. | L19: High | M19: Strike | N19: Execution | O19: Admin | P19: Not Submitted | Q19: PDD | R19: Enhancement to existing system
A20: 15 | B20: Okamura Settlement Compliance | C20: Gonzalez, Tiffany | D20: Active | E20: 81 | F20: Settlement compliance has elevated legal/compliance value. | G20: 2.7 | H20: Compliance execution and branch documentation create moderate complexity. | I20: =ROUND(E20-(G20*2.5),0) -> 74 | J20: =IF(D20<>"Active","Not Tiered",IF(I20>=80,"Full",IF(AND(E20<60,G20<2.5),"Mini","Standard"))) -> Standard | K20: =IF(D20<>"Active","Cancelled/inactive; excluded from active governance tier counts.",IF(J20="Full","Profiler band: VC "&TEXT(I20,"0")&" >= 80, so Full governance plan is required.",IF(J20="Mini","Profiler band: Value "&TEXT(E20,"0")&" < 60 and avg complexity "&TEXT(G20,"0.0")&" < 2.5, so Mini is allowed.","Profiler band: VC "&TEXT(I20,"0")&" < 80 and Mini gate not met ("&IF(E20>=60,"value >= 60","avg complexity >= 2.5")&"), so Standard."))) -> Profiler band: VC 74 < 80 and Mini gate not met (value >= 60), so Standard. | L20: Medium | M20: Project | N20: Execution | O20: UIB | P20: Submitted | Q20: PDD | R20: Documentation done per customer branch
A21: 16 | B21: Integrity Data Hub (IDH) Enhancements | C21: Chandrapal, Deepak | D21: Active | E21: 82 | F21: Integrity data hub enhancements carry high data/integrity value. | G21: 3.4 | H21: Data hub enhancements and alignment dependencies raise complexity. | I21: =ROUND(E21-(G21*2.5),0) -> 74 | J21: =IF(D21<>"Active","Not Tiered",IF(I21>=80,"Full",IF(AND(E21<60,G21<2.5),"Mini","Standard"))) -> Standard | K21: =IF(D21<>"Active","Cancelled/inactive; excluded from active governance tier counts.",IF(J21="Full","Profiler band: VC "&TEXT(I21,"0")&" >= 80, so Full governance plan is required.",IF(J21="Mini","Profiler band: Value "&TEXT(E21,"0")&" < 60 and avg complexity "&TEXT(G21,"0.0")&" < 2.5, so Mini is allowed.","Profiler band: VC "&TEXT(I21,"0")&" < 80 and Mini gate not met ("&IF(E21>=60,"value >= 60","avg complexity >= 2.5")&"), so Standard."))) -> Profiler band: VC 74 < 80 and Mini gate not met (value >= 60), so Standard. | L21: Medium | M21: Project | N21: Execution | O21: ITB | P21: Not Submitted | Q21: TGD | R21: Recommendation to align with Core2026, have to understand timeline in association with ACES and FAST. Tax Branch to update following discussions with AMB and FAST.
A22: 17 | B22: DOL USPS In-Person Identity Proofing for UI Claimants | C22: Chandrapal, Deepak | D22: Active | E22: 84 | F22: Identity proofing for UI claimants has high program integrity/customer value. | G22: 2.7 | H22: External USPS/DOL identity process and UI claimant workflow create moderate complexity. | I22: =ROUND(E22-(G22*2.5),0) -> 77 | J22: =IF(D22<>"Active","Not Tiered",IF(I22>=80,"Full",IF(AND(E22<60,G22<2.5),"Mini","Standard"))) -> Standard | K22: =IF(D22<>"Active","Cancelled/inactive; excluded from active governance tier counts.",IF(J22="Full","Profiler band: VC "&TEXT(I22,"0")&" >= 80, so Full governance plan is required.",IF(J22="Mini","Profiler band: Value "&TEXT(E22,"0")&" < 60 and avg complexity "&TEXT(G22,"0.0")&" < 2.5, so Mini is allowed.","Profiler band: VC "&TEXT(I22,"0")&" < 80 and Mini gate not met ("&IF(E22>=60,"value >= 60","avg complexity >= 2.5")&"), so Standard."))) -> Profiler band: VC 77 < 80 and Mini gate not met (value >= 60), so Standard. | L22: Medium | M22: Project | N22: Completed | O22: UIB | P22: Submitted | Q22: TGD | R22: Charter and Schedule completed for this effort. Most of the plans completed via meetings, meeting notes, and input in charter
A23: 18 | B23: UI Online - Appeals Portal | C23: Joji, Jerin | D23: Active | E23: 84 | F23: UI Online appeals functionality carries high customer/program value. | G23: 2.7 | H23: Portal and appeals workflow scope create moderate complexity. | I23: =ROUND(E23-(G23*2.5),0) -> 77 | J23: =IF(D23<>"Active","Not Tiered",IF(I23>=80,"Full",IF(AND(E23<60,G23<2.5),"Mini","Standard"))) -> Standard | K23: =IF(D23<>"Active","Cancelled/inactive; excluded from active governance tier counts.",IF(J23="Full","Profiler band: VC "&TEXT(I23,"0")&" >= 80, so Full governance plan is required.",IF(J23="Mini","Profiler band: Value "&TEXT(E23,"0")&" < 60 and avg complexity "&TEXT(G23,"0.0")&" < 2.5, so Mini is allowed.","Profiler band: VC "&TEXT(I23,"0")&" < 80 and Mini gate not met ("&IF(E23>=60,"value >= 60","avg complexity >= 2.5")&"), so Standard."))) -> Profiler band: VC 77 < 80 and Mini gate not met (value >= 60), so Standard. | L23: Medium | M23: Project | N23: Planning | O23: UIB | P23: In Progress | Q23: TGD | R23: Starting Project
A24: 19 | B24: Infrastructure Security Assessment | C24: Kidd, Christy | D24: Active | E24: 52 | F24: Analysis/assessment note and non-SDLC status keep value below Mini ceiling. | G24: 1.7 | H24: Assessment-only work is low complexity compared with delivery implementation. | I24: =ROUND(E24-(G24*2.5),0) -> 48 | J24: =IF(D24<>"Active","Not Tiered",IF(I24>=80,"Full",IF(AND(E24<60,G24<2.5),"Mini","Standard"))) -> Mini | K24: =IF(D24<>"Active","Cancelled/inactive; excluded from active governance tier counts.",IF(J24="Full","Profiler band: VC "&TEXT(I24,"0")&" >= 80, so Full governance plan is required.",IF(J24="Mini","Profiler band: Value "&TEXT(E24,"0")&" < 60 and avg complexity "&TEXT(G24,"0.0")&" < 2.5, so Mini is allowed.","Profiler band: VC "&TEXT(I24,"0")&" < 80 and Mini gate not met ("&IF(E24>=60,"value >= 60","avg complexity >= 2.5")&"), so Standard."))) -> Profiler band: Value 52 < 60 and avg complexity 1.7 < 2.5, so Mini is allowed. | L24: High | M24: Strike | N24: Execution | O24: ITB | P24: Submitted | Q24: Cybersecurity | R24: Not an official SDLC project. This was an analysis effort.
A25: 20 | B25: ID Verification Case Tracking (ARPA Integrity Grant) | C25: Mishra, Anjana | D25: Active | E25: 68 | F25: ID verification case tracking has program integrity value, but scope appears bounded. | G25: 2 | H25: Case-tracking change is moderate but not modernization-level complexity. | I25: =ROUND(E25-(G25*2.5),0) -> 63 | J25: =IF(D25<>"Active","Not Tiered",IF(I25>=80,"Full",IF(AND(E25<60,G25<2.5),"Mini","Standard"))) -> Standard | K25: =IF(D25<>"Active","Cancelled/inactive; excluded from active governance tier counts.",IF(J25="Full","Profiler band: VC "&TEXT(I25,"0")&" >= 80, so Full governance plan is required.",IF(J25="Mini","Profiler band: Value "&TEXT(E25,"0")&" < 60 and avg complexity "&TEXT(G25,"0.0")&" < 2.5, so Mini is allowed.","Profiler band: VC "&TEXT(I25,"0")&" < 80 and Mini gate not met ("&IF(E25>=60,"value >= 60","avg complexity >= 2.5")&"), so Standard."))) -> Profiler band: VC 63 < 80 and Mini gate not met (value >= 60), so Standard. | L25: Medium | M25: Project | N25: Execution | O25: UIB | P25: Not Submitted | Q25: PDD | R25: Not Submitted — Expected 04/10/2026
A26: 21 | B26: Field Information System (FIS) | C26: Ramaseshan, Sankar | D26: Active | E26: 81 | F26: Multi-branch field information system suggests high operational value. | G26: 3.3 | H26: Multi-branch system scope creates high complexity. | I26: =ROUND(E26-(G26*2.5),0) -> 73 | J26: =IF(D26<>"Active","Not Tiered",IF(I26>=80,"Full",IF(AND(E26<60,G26<2.5),"Mini","Standard"))) -> Standard | K26: =IF(D26<>"Active","Cancelled/inactive; excluded from active governance tier counts.",IF(J26="Full","Profiler band: VC "&TEXT(I26,"0")&" >= 80, so Full governance plan is required.",IF(J26="Mini","Profiler band: Value "&TEXT(E26,"0")&" < 60 and avg complexity "&TEXT(G26,"0.0")&" < 2.5, so Mini is allowed.","Profiler band: VC "&TEXT(I26,"0")&" < 80 and Mini gate not met ("&IF(E26>=60,"value >= 60","avg complexity >= 2.5")&"), so Standard."))) -> Profiler band: VC 73 < 80 and Mini gate not met (value >= 60), so Standard. | L26: Medium | M26: Project | N26: Execution | O26: WSB/UIB/TAX | P26: Submitted | Q26: TGD | R26: Stored within the Second submissions
A27: 22 | B27: SIDES Governance and Exchange Project | C27: Iwu, Michael | D27: Active | E27: 70 | F27: Governance/exchange scope is important, but naming suggests bounded value compared with core modernization. | G27: 2.7 | H27: Governance/exchange work has moderate coordination complexity. | I27: =ROUND(E27-(G27*2.5),0) -> 63 | J27: =IF(D27<>"Active","Not Tiered",IF(I27>=80,"Full",IF(AND(E27<60,G27<2.5),"Mini","Standard"))) -> Standard | K27: =IF(D27<>"Active","Cancelled/inactive; excluded from active governance tier counts.",IF(J27="Full","Profiler band: VC "&TEXT(I27,"0")&" >= 80, so Full governance plan is required.",IF(J27="Mini","Profiler band: Value "&TEXT(E27,"0")&" < 60 and avg complexity "&TEXT(G27,"0.0")&" < 2.5, so Mini is allowed.","Profiler band: VC "&TEXT(I27,"0")&" < 80 and Mini gate not met ("&IF(E27>=60,"value >= 60","avg complexity >= 2.5")&"), so Standard."))) -> Profiler band: VC 63 < 80 and Mini gate not met (value >= 60), so Standard. | L27: Medium | M27: Project | N27: Execution | O27: UIB | P27: Not Submitted | Q27: TGD
A28: 23 | B28: Federal Tax Information Secure Data Share | C28: Silva, Chaminda | D28: Active | E28: 58 | F28: Strike/existing-system enhancement signal keeps value below Mini ceiling. | G28: 1.7 | H28: Secure data share enhancement appears bounded and low complexity. | I28: =ROUND(E28-(G28*2.5),0) -> 54 | J28: =IF(D28<>"Active","Not Tiered",IF(I28>=80,"Full",IF(AND(E28<60,G28<2.5),"Mini","Standard"))) -> Mini | K28: =IF(D28<>"Active","Cancelled/inactive; excluded from active governance tier counts.",IF(J28="Full","Profiler band: VC "&TEXT(I28,"0")&" >= 80, so Full governance plan is required.",IF(J28="Mini","Profiler band: Value "&TEXT(E28,"0")&" < 60 and avg complexity "&TEXT(G28,"0.0")&" < 2.5, so Mini is allowed.","Profiler band: VC "&TEXT(I28,"0")&" < 80 and Mini gate not met ("&IF(E28>=60,"value >= 60","avg complexity >= 2.5")&"), so Standard."))) -> Profiler band: Value 58 < 60 and avg complexity 1.7 < 2.5, so Mini is allowed. | L28: High | M28: Strike | N28: Completed | O28: ITB | P28: Not Submitted | Q28: ISD | R28: Not needed for this effort, enhancement to the existing system
A29: 24 | B29: NLAB LWDA Hub Building Move | C29: Boyle, Grace | D29: Active | E29: 82 | F29: Enterprise hub move has high operational value, but not a core application modernization. | G29: 3.3 | H29: Building move involves enterprise logistics/physical security and coordination complexity. | I29: =ROUND(E29-(G29*2.5),0) -> 74 | J29: =IF(D29<>"Active","Not Tiered",IF(I29>=80,"Full",IF(AND(E29<60,G29<2.5),"Mini","Standard"))) -> Standard | K29: =IF(D29<>"Active","Cancelled/inactive; excluded from active governance tier counts.",IF(J29="Full","Profiler band: VC "&TEXT(I29,"0")&" >= 80, so Full governance plan is required.",IF(J29="Mini","Profiler band: Value "&TEXT(E29,"0")&" < 60 and avg complexity "&TEXT(G29,"0.0")&" < 2.5, so Mini is allowed.","Profiler band: VC "&TEXT(I29,"0")&" < 80 and Mini gate not met ("&IF(E29>=60,"value >= 60","avg complexity >= 2.5")&"), so Standard."))) -> Profiler band: VC 74 < 80 and Mini gate not met (value >= 60), so Standard. | L29: Medium | M29: Project | N29: Execution | O29: ENT | P29: Submitted | Q29: TGD | R29: Physical security noted, documentation provided in second submission folder
A30: 25 | B30: UI Space Force | C30: Jondle, Alan | D30: Active | E30: 75 | F30: UI-specific effort has meaningful value, but notes suggest limited incremental documentation scope. | G30: 2 | H30: Implementation appears scoped, with existing UI Online security artifacts. | I30: =ROUND(E30-(G30*2.5),0) -> 70 | J30: =IF(D30<>"Active","Not Tiered",IF(I30>=80,"Full",IF(AND(E30<60,G30<2.5),"Mini","Standard"))) -> Standard | K30: =IF(D30<>"Active","Cancelled/inactive; excluded from active governance tier counts.",IF(J30="Full","Profiler band: VC "&TEXT(I30,"0")&" >= 80, so Full governance plan is required.",IF(J30="Mini","Profiler band: Value "&TEXT(E30,"0")&" < 60 and avg complexity "&TEXT(G30,"0.0")&" < 2.5, so Mini is allowed.","Profiler band: VC "&TEXT(I30,"0")&" < 80 and Mini gate not met ("&IF(E30>=60,"value >= 60","avg complexity >= 2.5")&"), so Standard."))) -> Profiler band: VC 70 < 80 and Mini gate not met (value >= 60), so Standard. | L30: Medium | M30: Project | N30: Completed | O30: UIB | P30: Submitted | Q30: TGD | R30: UI Online keeps its SSP up to date on its own so we did not do that as part of either of those 2 projects. PIA completed for this effort, BIA waived.
A31: 26 | B31: PFL Bonding Automation | C31: Madan, Supreet | D31: Active | E31: 57 | F31: Strike/quick-win backlog-reduction note keeps this below the Mini value ceiling. | G31: 1.7 | H31: Quick-win automation effort is low complexity compared with a formal project. | I31: =ROUND(E31-(G31*2.5),0) -> 53 | J31: =IF(D31<>"Active","Not Tiered",IF(I31>=80,"Full",IF(AND(E31<60,G31<2.5),"Mini","Standard"))) -> Mini | K31: =IF(D31<>"Active","Cancelled/inactive; excluded from active governance tier counts.",IF(J31="Full","Profiler band: VC "&TEXT(I31,"0")&" >= 80, so Full governance plan is required.",IF(J31="Mini","Profiler band: Value "&TEXT(E31,"0")&" < 60 and avg complexity "&TEXT(G31,"0.0")&" < 2.5, so Mini is allowed.","Profiler band: VC "&TEXT(I31,"0")&" < 80 and Mini gate not met ("&IF(E31>=60,"value >= 60","avg complexity >= 2.5")&"), so Standard."))) -> Profiler band: Value 57 < 60 and avg complexity 1.7 < 2.5, so Mini is allowed. | L31: High | M31: Strike | N31: Execution | O31: DIB | P31: Not Submitted | Q31: EDDNext | R31: The Bonding Automation project is similar to strike teams recommendation where the team was quickly trying to reduce the PFL backlog to get few quick wins. Traditional projects artifacts were not created.
A32: 27 | B32: CO Data Center Migration to TMS Cloud | C32: Chandrapal, Deepak | D32: Active | E32: 76 | F32: Data-center migration has meaningful technical value but appears focused on existing server documentation. | G32: 3.4 | H32: Server/cloud migration is technically complex even if documentation uses existing materials. | I32: =ROUND(E32-(G32*2.5),0) -> 68 | J32: =IF(D32<>"Active","Not Tiered",IF(I32>=80,"Full",IF(AND(E32<60,G32<2.5),"Mini","Standard"))) -> Standard | K32: =IF(D32<>"Active","Cancelled/inactive; excluded from active governance tier counts.",IF(J32="Full","Profiler band: VC "&TEXT(I32,"0")&" >= 80, so Full governance plan is required.",IF(J32="Mini","Profiler band: Value "&TEXT(E32,"0")&" < 60 and avg complexity "&TEXT(G32,"0.0")&" < 2.5, so Mini is allowed.","Profiler band: VC "&TEXT(I32,"0")&" < 80 and Mini gate not met ("&IF(E32>=60,"value >= 60","avg complexity >= 2.5")&"), so Standard."))) -> Profiler band: VC 68 < 80 and Mini gate not met (value >= 60), so Standard. | L32: Medium | M32: Project | N32: Execution | O32: ITB | P32: Not Submitted | Q32: TGD | R32: Migration of servers to TMS Cloud used existing server documentation
A33: 28 | B33: DI Vital Forms Translations | C33: Jain, Manish | D33: Active | E33: 55 | F33: Forms translation is valuable but bounded and below Mini value ceiling. | G33: 2 | H33: Translation/forms scope is limited and low-to-moderate complexity. | I33: =ROUND(E33-(G33*2.5),0) -> 50 | J33: =IF(D33<>"Active","Not Tiered",IF(I33>=80,"Full",IF(AND(E33<60,G33<2.5),"Mini","Standard"))) -> Mini | K33: =IF(D33<>"Active","Cancelled/inactive; excluded from active governance tier counts.",IF(J33="Full","Profiler band: VC "&TEXT(I33,"0")&" >= 80, so Full governance plan is required.",IF(J33="Mini","Profiler band: Value "&TEXT(E33,"0")&" < 60 and avg complexity "&TEXT(G33,"0.0")&" < 2.5, so Mini is allowed.","Profiler band: VC "&TEXT(I33,"0")&" < 80 and Mini gate not met ("&IF(E33>=60,"value >= 60","avg complexity >= 2.5")&"), so Standard."))) -> Profiler band: Value 55 < 60 and avg complexity 2.0 < 2.5, so Mini is allowed. | L33: High | M33: Project | N33: Execution | O33: DIB | P33: Submitted | Q33: ISD | R33: Translation, Ajit and Adam Sponsors
A34: 29 | B34: DI / PFL Duplicate Claims | C34: Madan, Supreet | D34: Active | E34: 59 | F34: Strike/quick-win backlog-reduction note keeps this just under the Mini value ceiling. | G34: 1.7 | H34: Duplicate-claims quick-win effort is low complexity. | I34: =ROUND(E34-(G34*2.5),0) -> 55 | J34: =IF(D34<>"Active","Not Tiered",IF(I34>=80,"Full",IF(AND(E34<60,G34<2.5),"Mini","Standard"))) -> Mini | K34: =IF(D34<>"Active","Cancelled/inactive; excluded from active governance tier counts.",IF(J34="Full","Profiler band: VC "&TEXT(I34,"0")&" >= 80, so Full governance plan is required.",IF(J34="Mini","Profiler band: Value "&TEXT(E34,"0")&" < 60 and avg complexity "&TEXT(G34,"0.0")&" < 2.5, so Mini is allowed.","Profiler band: VC "&TEXT(I34,"0")&" < 80 and Mini gate not met ("&IF(E34>=60,"value >= 60","avg complexity >= 2.5")&"), so Standard."))) -> Profiler band: Value 59 < 60 and avg complexity 1.7 < 2.5, so Mini is allowed. | L34: High | M34: Strike | N34: Execution | O34: DIB | P34: Not Submitted | Q34: EDDNext | R34: The Duplicate Claims is similar to strike teams recommendation where the team was quickly trying to reduce the PFL backlog to get quick wins. Traditional projects artifacts were not created.
A35: 30 | B35: CalJOBS - OBBBA Medicaid Work Requirements | C35: Narendra, PDD Division Chief | D35: Active | E35: 73 | F35: CalJOBS and work requirements indicate meaningful program value. | G35: 3.2 | H35: On-hold status aside, requirements/workflow changes create above-average complexity. | I35: =ROUND(E35-(G35*2.5),0) -> 65 | J35: =IF(D35<>"Active","Not Tiered",IF(I35>=80,"Full",IF(AND(E35<60,G35<2.5),"Mini","Standard"))) -> Standard | K35: =IF(D35<>"Active","Cancelled/inactive; excluded from active governance tier counts.",IF(J35="Full","Profiler band: VC "&TEXT(I35,"0")&" >= 80, so Full governance plan is required.",IF(J35="Mini","Profiler band: Value "&TEXT(E35,"0")&" < 60 and avg complexity "&TEXT(G35,"0.0")&" < 2.5, so Mini is allowed.","Profiler band: VC "&TEXT(I35,"0")&" < 80 and Mini gate not met ("&IF(E35>=60,"value >= 60","avg complexity >= 2.5")&"), so Standard."))) -> Profiler band: VC 65 < 80 and Mini gate not met (value >= 60), so Standard. | L35: Medium | M35: Project | N35: On Hold | O35: WSB | P35: On Hold | Q35: PDD | R35: ON HOLD
A36: 31 | B36: Case Management System - IAD | C36: Mishra, Anjana | D36: Active | E36: 78 | F36: Case-management system scope has meaningful operational value. | G36: 3.4 | H36: Case-management system work suggests high technical/workflow complexity. | I36: =ROUND(E36-(G36*2.5),0) -> 70 | J36: =IF(D36<>"Active","Not Tiered",IF(I36>=80,"Full",IF(AND(E36<60,G36<2.5),"Mini","Standard"))) -> Standard | K36: =IF(D36<>"Active","Cancelled/inactive; excluded from active governance tier counts.",IF(J36="Full","Profiler band: VC "&TEXT(I36,"0")&" >= 80, so Full governance plan is required.",IF(J36="Mini","Profiler band: Value "&TEXT(E36,"0")&" < 60 and avg complexity "&TEXT(G36,"0.0")&" < 2.5, so Mini is allowed.","Profiler band: VC "&TEXT(I36,"0")&" < 80 and Mini gate not met ("&IF(E36>=60,"value >= 60","avg complexity >= 2.5")&"), so Standard."))) -> Profiler band: VC 70 < 80 and Mini gate not met (value >= 60), so Standard. | L36: Medium | M36: Project | N36: Execution | O36: UIB | P36: Not Submitted | Q36: PDD | R36: Not Submitted — Expected 04/10/2026
A37: 32 | B37: MS Teams Phone Project (SoftPhone) | C37: Hummel, Tanya | D37: Active | E37: 66 | F37: Enterprise softphone effort has operational value, but on-hold/docs-note lowers urgency/value. | G37: 3.1 | H37: Enterprise telephony rollout is above-average technical and adoption complexity. | I37: =ROUND(E37-(G37*2.5),0) -> 58 | J37: =IF(D37<>"Active","Not Tiered",IF(I37>=80,"Full",IF(AND(E37<60,G37<2.5),"Mini","Standard"))) -> Standard | K37: =IF(D37<>"Active","Cancelled/inactive; excluded from active governance tier counts.",IF(J37="Full","Profiler band: VC "&TEXT(I37,"0")&" >= 80, so Full governance plan is required.",IF(J37="Mini","Profiler band: Value "&TEXT(E37,"0")&" < 60 and avg complexity "&TEXT(G37,"0.0")&" < 2.5, so Mini is allowed.","Profiler band: VC "&TEXT(I37,"0")&" < 80 and Mini gate not met ("&IF(E37>=60,"value >= 60","avg complexity >= 2.5")&"), so Standard."))) -> Profiler band: VC 58 < 80 and Mini gate not met (value >= 60), so Standard. | L37: Medium | M37: Project | N37: On Hold | O37: ENT | P37: On Hold | Q37: TGD | R37: Docs submitted directly — no standard intake form.
A38: 33 | B38: CIMS / MIS Replacement | C38: Rajasekaran, Aparnaa | D38: Active | E38: 70 | F38: Replacement scope is valuable, but completed status and lower priority keep value moderate. | G38: 3.4 | H38: Replacement work carries high complexity even at moderate value. | I38: =ROUND(E38-(G38*2.5),0) -> 62 | J38: =IF(D38<>"Active","Not Tiered",IF(I38>=80,"Full",IF(AND(E38<60,G38<2.5),"Mini","Standard"))) -> Standard | K38: =IF(D38<>"Active","Cancelled/inactive; excluded from active governance tier counts.",IF(J38="Full","Profiler band: VC "&TEXT(I38,"0")&" >= 80, so Full governance plan is required.",IF(J38="Mini","Profiler band: Value "&TEXT(E38,"0")&" < 60 and avg complexity "&TEXT(G38,"0.0")&" < 2.5, so Mini is allowed.","Profiler band: VC "&TEXT(I38,"0")&" < 80 and Mini gate not met ("&IF(E38>=60,"value >= 60","avg complexity >= 2.5")&"), so Standard."))) -> Profiler band: VC 62 < 80 and Mini gate not met (value >= 60), so Standard. | L38: Medium | M38: Project | N38: Completed | O38: LDCB | P38: Submitted | Q38: TGD
A39: 34 | B39: WSB Lobby Environment Modernization | C39: Jondle, Alan | D39: Active | E39: 70 | F39: Lobby modernization has customer-service value, but appears narrower than enterprise platform work. | G39: 3.4 | H39: Modernization and customer-facing environment changes create high complexity. | I39: =ROUND(E39-(G39*2.5),0) -> 62 | J39: =IF(D39<>"Active","Not Tiered",IF(I39>=80,"Full",IF(AND(E39<60,G39<2.5),"Mini","Standard"))) -> Standard | K39: =IF(D39<>"Active","Cancelled/inactive; excluded from active governance tier counts.",IF(J39="Full","Profiler band: VC "&TEXT(I39,"0")&" >= 80, so Full governance plan is required.",IF(J39="Mini","Profiler band: Value "&TEXT(E39,"0")&" < 60 and avg complexity "&TEXT(G39,"0.0")&" < 2.5, so Mini is allowed.","Profiler band: VC "&TEXT(I39,"0")&" < 80 and Mini gate not met ("&IF(E39>=60,"value >= 60","avg complexity >= 2.5")&"), so Standard."))) -> Profiler band: VC 62 < 80 and Mini gate not met (value >= 60), so Standard. | L39: Medium | M39: Project | N39: Completed | O39: WSB | P39: Submitted | Q39: TGD | R39: UI Online keeps its SSP up to date on its own so we did not do that as part of either of those 2 projects.
A40: 35 | B40: ITB Service Desk Modernization | C40: Atkinson, Oksana | D40: Active | E40: 78 | F40: Service desk modernization has strong internal service value. | G40: 3.4 | H40: Modernization/process/tooling changes create high complexity. | I40: =ROUND(E40-(G40*2.5),0) -> 70 | J40: =IF(D40<>"Active","Not Tiered",IF(I40>=80,"Full",IF(AND(E40<60,G40<2.5),"Mini","Standard"))) -> Standard | K40: =IF(D40<>"Active","Cancelled/inactive; excluded from active governance tier counts.",IF(J40="Full","Profiler band: VC "&TEXT(I40,"0")&" >= 80, so Full governance plan is required.",IF(J40="Mini","Profiler band: Value "&TEXT(E40,"0")&" < 60 and avg complexity "&TEXT(G40,"0.0")&" < 2.5, so Mini is allowed.","Profiler band: VC "&TEXT(I40,"0")&" < 80 and Mini gate not met ("&IF(E40>=60,"value >= 60","avg complexity >= 2.5")&"), so Standard."))) -> Profiler band: VC 70 < 80 and Mini gate not met (value >= 60), so Standard. | L40: Medium | M40: Project | N40: Execution | O40: ITB | P40: Submitted | Q40: TGD | R40: The project has the artifacts available
...

Sheet Scoring Rules
A1: Scoring Rules and Assumptions
A3: Rule Area | B3: Defensible working rule | C3: Why it matters
A4: Formula | B4: Estimated VC = Estimated Value − (Estimated Avg Complexity × 2.5) | C4: Keeps the score aligned to the value-to-complexity model already being discussed.
A5: Full | B5: Estimated VC > 79 | C5: Anything above 79 is treated as requiring a Full governance plan.
A6: Mini | B6: Estimated Value < 60 AND Estimated Avg Complexity ≤ 2.5 | C6: Prevents high-value efforts from being called Mini just because they are a Strike, pilot, or POC.
A7: Standard | B7: Everything active that is not Full and does not pass the Mini gate | C7: Captures medium/high-value work, moderate complexity, and low-value-but-complex work.
A8: Name/type signals | B8: POC, pilot, Strike, quick win, analysis-only, enhancement, existing-system configuration | C8: These can lower value/complexity, but they do not override the Mini gate.
A9: High-value signals | B9: Core benefit payments, claims, identity proofing, modernization, enterprise platform, statutory/compliance, data warehouse | C9: These raise the value estimate and can push the VC score into Full.
A10: Complexity signals | B10: Modernization, replacement, migration, multi-branch scope, cloud/data/platform, identity/security, enterprise rollout | C10: These raise the complexity estimate and reduce the VC score while also making the work less Mini-like.
A11: Confidence | B11: High where the name/type/notes clearly trigger a rule; Medium where the score relies more heavily on project-name inference | C11: Keeps the estimate honest and makes the judgment auditable.
A13: Methodology & Defensibility
A14: Topic | B14: Position / Method | C14: Why it is defensible
A15: Formula (Profiler-faithful) | B15: All VC values were recomputed to match the ESPMO Profiler source exactly: VC = round(Total Value − (average of business and technical complexity × 2.5)). VC is rounded to the nearest integer (Math.round, half-up), matching the tool. No value-level rounding-to-5 is applied because the Profiler does not do this — Value is a sum of four weighted drivers and lands on whatever integer they total. | C15: Replaces the earlier guessed numbers and the ">79" cutoff with the tool’s real arithmetic and ≥80 cutoff. Every VC in this sheet now equals what the Profiler would output for the same Value and average-complexity inputs, so the sheet is reconcilable line-by-line against a live Profiler run.
A16: Band ladder | B16: Banding uses the Profiler ladder verbatim: VC ≥ 80 → Full; else Value < 60 AND avg complexity < 2.5 → Mini; else Standard. The Mini gate is strict-less-than on both Value (<60) and complexity (<2.5), matching the source. | C16: Prevents drift from the canonical 4-tier model. The strict < 2.5 complexity gate (not ≤) is the tool’s actual condition; using ≤ here would have mis-tiered borderline rows.
A17: EDD Next / PAL escalation NOT auto-applied | B17: The Profiler also has an EDD Next floor (forces Full) and a PAL Tier 4 path, both driven by in-tool flags. These are NOT inferred from the ITB Division column. A division labelled "EDDNext" does not by itself set the floor; the flag is set inside the Profiler per project. | C17: Avoids a false escalation: inferring the floor from the division label would wrongly push low-VC quick-win efforts (e.g. PFL Bonding Automation, DI/PFL Duplicate Claims) to Full. Escalations are left off pending a confirmed flag, which is the conservative, defensible default.
A18: Input basis (Value & avg complexity) | B18: Value and average complexity remain ESTIMATES inferred from project name, type, phase, and intake notes — the Profiler-faithful step recomputes the VERDICT (VC and band) from those inputs, it does not claim the inputs themselves are Profiler-measured. | C18: Cleanly separates rule-faithfulness (now exact) from input-estimation (still judgment). A reviewer can accept the recomputed banding while still re-estimating any individual Value or complexity.
A19: Fraud Hotline reframe | B19: EDD Fraud Hotline (Speech-to-Text), marked *, was reframed as a POC/prove-the-capability effort (Value lowered 90→85). At avg complexity 2.8 this yields VC 78 → Standard under the ≥80 ladder. Remains off the Executive Report roster — flagged for reconciliation. | C19: Applies the same POC value-discount the Profiler logic and this sheet already use for other POC/Strike efforts; the change is rule-consistent rather than an ad-hoc exception, and the roster gap is surfaced proactively.
A20: Scope of this tab | B20: Active tiering only. The single Not Tiered row (cancelled, no intake) is scored for context but excluded from tier counts and guardrails. Active denominator = 48 of 49 rows. | C20: Keeps tier shares and guardrail checks undistorted by inactive work.
