Workbook

Sheet Read Me
A1: ⚠ THIS IS A TEMPLATE — NOT A LIVE PROJECT SCHEDULE ⚠
A2: Anticipation: the enterprise PPM tool (once selected) will produce the authoritative, project-specific schedule. This workbook is a reusable starter scaffold supporting both Waterfall and Agile delivery, combining EDD PM RACI (Most recent version), the Secure-by-Design guide, and PMI/PMBOK-standard PM deliverables.
B4: KEY IN THIS VERSION — BASELINE PHASE COLUMN
B5: Every deliverable has TWO lifecycle anchors: where active work STARTS, and where the final version is BASELINED. The new 'Baseline Phase' column (col F) shows where each deliverable is approved/finalized.
B6: • 23 deliverables: Baseline Phase = Start Phase (same-phase, no span).
B7: • 20 deliverables: Baseline Phase is later than Start Phase — highlighted with peach background and → arrow.
B8: Example: Requirements Traceability Matrix (RTM) starts active work in Plan but isn't baselined until end of Test.
B10: WHAT'S IN THIS WORKBOOK
B11: • Schedule — PM-expected deliverables with Source / Methodology / Baseline Phase classifications and Profiler Required? filtering.
B12: • Engagement Matrix — The Profiler provides the suggested matrix; the schedule keeps a Review and Revise Engagement Matrix task for PM follow-through.
B13: • Phase Summary — Auto-rollup by CA-PMF phase, baseline phase, methodology, and source.
B14: • Contacts — Seven EDD support groups referenced in the Secure-by-Design guide.
B16: METHODOLOGY COVERAGE — WORKS FOR BOTH WATERFALL AND AGILE
B17: Each deliverable is tagged with one of three values in the Methodology column:
... B77: • Aligned to CA-PMF; informed by SIMM §19.
A80: Replace this template with the official PPM tool schedule once that tool is in place.

Sheet Schedule
A1: ⚠ TEMPLATE — NOT A LIVE PROJECT SCHEDULE ⚠
A2: PM-expected deliverables schedule with Methodology classification (Agile / Waterfall / Both). Combines EDD PM RACI, Secure-by-Design guide, and PMI/PMBOK standards. Phase-parallel scheduling model.
A4: Project Name: | G4: LWDA Intune Device Migration
A5: Project Manager: | G5: Delondi Kintaudi
A6: Project Start Date: | G6: 46204
A7: Project End Date: | G7: =IF(COUNT(N12:N59)>0,TEXT(MAX(N12:N59),"m/d/yyyy")&" (actual)",TEXT(MAX(L12:L59),"m/d/yyyy")&" (planned)") -> 7/21/2027 (planned)
A8: Schedule Last Updated: | G8: =TODAY() -> 46190
A9: Project Type: | G9: Waterfall
A10: Legend: Blue = user input • Source: teal=RACI, gold=Secure-by-Design, violet=PMI • Methodology: orange=Agile, indigo=Waterfall, green=Both • ▶ = phase gate • ║ = parallel sibling
A11: Deliverable ID | B11: Profiler Required? | C11: Schedule Category | D11: Source | E11: Methodology | F11: CA-PMF Phase | G11: Execute Sub-Phase | H11: Baseline Phase | I11: Deliverable / Task | J11: Duration (bus. days) | K11: Planned Start | L11: Planned End | M11: Actual Start | N11: Actual End | O11: Predecessor / Parallelism | P11: Responsible (R) | Q11: Status | R11: % Complete | S11: Notes/Assumptions | T11: Comments | U11: Show?
A12: CON-01 | B12: Yes | C12: Governance & Management | D12: RACI | E12: Both | F12: Concept | G12: — | H12: Concept | I12: Obtain Work Intake Confirmation | J12: 1 | K12: =$G$6 -> 46204 | L12: =WORKDAY(K12,J12-1) -> 46204 | O12: Project Start | P12: Project Sponsor | Q12: Not Started | R12: 0 | U12: =IF(AND(OR($E12="Both",$E12=$G$9,$E12="None",$G$9="Hybrid",$G$9=""),OR($R$5="All",$R$5="",$C12=$R$5),OR($R$6="All deliverables",$R$6="",$B12="Yes")),"Show","Hide") -> Show
A13: INI-01 | B13: Yes | C13: Governance & Management | D13: RACI | E13: Both | F13: Initiate | G13: — | H13: → Close | I13: Develop Project Charter | J13: 10 | K13: =WORKDAY(MAX(L12:L12),1) -> 46205 | L13: =WORKDAY(K13,J13-1) -> 46218 | O13: ▶ After Concept | P13: Project Sponsor, IT Sponsor, Project Manager | Q13: Not Started | R13: 0 | U13: =IF(AND(OR($E13="Both",$E13=$G$9,$E13="None",$G$9="Hybrid",$G$9=""),OR($R$5="All",$R$5="",$C13=$R$5),OR($R$6="All deliverables",$R$6="",$B13="Yes")),"Show","Hide") -> Show
A14: INI-02 | B14: Yes | C14: Governance & Management | D14: PMI | E14: Both | F14: Initiate | G14: — | H14: → Close | I14: Develop Project Management Plan(s) | J14: 10 | K14: =K13 -> 46205 | L14: =WORKDAY(K14,J14-1) -> 46218 | O14: ║ Parallel with INI-01 | P14: Project Manager | Q14: Not Started | R14: 0 | S14: Defines decision rights and escalation paths. Approved by Steering Committee. | U14: =IF(AND(OR($E14="Both",$E14=$G$9,$E14="None",$G$9="Hybrid",$G$9=""),OR($R$5="All",$R$5="",$C14=$R$5),OR($R$6="All deliverables",$R$6="",$B14="Yes")),"Show","Hide") -> Show
A15: INI-03 | B15: Yes | C15: Governance & Management | D15: RACI | E15: Both | F15: Initiate | G15: — | H15: → Close | I15: Develop Stakeholder Register | J15: 5 | K15: =K13 -> 46205 | L15: =WORKDAY(K15,J15-1) -> 46211 | O15: ║ Parallel with INI-01 | P15: Project Sponsor, IT Sponsor, Project Manager | Q15: Not Started | R15: 0 | U15: =IF(AND(OR($E15="Both",$E15=$G$9,$E15="None",$G$9="Hybrid",$G$9=""),OR($R$5="All",$R$5="",$C15=$R$5),OR($R$6="All deliverables",$R$6="",$B15="Yes")),"Show","Hide") -> Show
A16: INI-04 | B16: Yes | C16: Governance & Management | D16: RACI | E16: Both | F16: Initiate | G16: — | H16: Initiate | I16: Review and Revise Engagement Matrix | J16: 5 | K16: =K13 -> 46205 | L16: =WORKDAY(K16,J16-1) -> 46211 | O16: ║ Parallel with INI-01 | P16: Project Sponsor, IT Sponsor, Project Manager | Q16: Not Started | R16: 0 | U16: =IF(AND(OR($E16="Both",$E16=$G$9,$E16="None",$G$9="Hybrid",$G$9=""),OR($R$5="All",$R$5="",$C16=$R$5),OR($R$6="All deliverables",$R$6="",$B16="Yes")),"Show","Hide") -> Show
A17: INI-05 | B17: Yes | C17: Governance & Management | D17: PMI | E17: Both | F17: Initiate | G17: — | H17: → Close | I17: Establish CRAID Log | J17: 5 | K17: =K13 -> 46205 | L17: =WORKDAY(K16,J16-1) -> 46211 | O17: ║ Parallel with INI-01 | P17: Project Manager | Q17: Not Started | R17: 0 | S17: Initial setup duration; maintained continuously through Close. | U17: =IF(AND(OR($E17="Both",$E17=$G$9,$E17="None",$G$9="Hybrid",$G$9=""),OR($R$5="All",$R$5="",$C17=$R$5),OR($R$6="All deliverables",$R$6="",$B17="Yes")),"Show","Hide") -> Show
A18: INI-06 | B18: Yes | C18: Delivery & Execution | D18: RACI | E18: Both | F18: Initiate | G18: — | H18: → Close | I18: Engage Security Team (refer to CSD Cybersecurity Standards in Notes) | J18: 5 | K18: =K13 -> 46205 | L18: =WORKDAY(K17,J17-1) -> 46211 | O18: ║ Parallel with INI-01 | P18: IT System Owner | Q18: Not Started | R18: 0 | S18: CyberSecurity Link | U18: =IF(AND(OR($E18="Both",$E18=$G$9,$E18="None",$G$9="Hybrid",$G$9=""),OR($R$5="All",$R$5="",$C18=$R$5),OR($R$6="All deliverables",$R$6="",$B18="Yes")),"Show","Hide") -> Show
A19: INI-07 | B19: Yes | C19: Governance & Management | D19: RACI | E19: Both | F19: Initiate | G19: — | H19: → Close | I19: Develop Enterprise Architecture Engagement Plan | J19: 10 | K19: =K13 -> 46205 | L19: =WORKDAY(K18,J18-1) -> 46211 | O19: ║ Parallel with INI-01 | P19: IT System Owner | Q19: Not Started | R19: 0 | U19: =IF(AND(OR($E19="Both",$E19=$G$9,$E19="None",$G$9="Hybrid",$G$9=""),OR($R$5="All",$R$5="",$C19=$R$5),OR($R$6="All deliverables",$R$6="",$B19="Yes")),"Show","Hide") -> Show
A20: INI-08 | B20: Yes | C20: Governance & Management | D20: RACI | E20: Both | F20: Initiate | G20: — | H20: Initiate | I20: Draft Release Readiness Review (RRR) Checklist | J20: 5 | K20: =K13 -> 46205 | L20: =WORKDAY(K19,J19-1) -> 46218 | O20: ║ Parallel with INI-01 | P20: Project Manager | Q20: Not Started | R20: 0 | U20: =IF(AND(OR($E20="Both",$E20=$G$9,$E20="None",$G$9="Hybrid",$G$9=""),OR($R$5="All",$R$5="",$C20=$R$5),OR($R$6="All deliverables",$R$6="",$B20="Yes")),"Show","Hide") -> Show
A21: PLN-01 | B21: Yes | C21: Governance & Management | D21: PMI | E21: Both | F21: Plan | G21: — | H21: → Close | I21: Consolidate Project Management Plan(s) | J21: 30 | K21: =WORKDAY(MAX(L13:L19),1) -> 46219 | L21: =WORKDAY(K20,J20-1) -> 46211 | O21: ▶ After Initiate | P21: Project Manager | Q21: Not Started | R21: 0 | S21: Consolidates 8 RACI subsidiary plans (Risk/Issue/Change, Communication, Scope, Requirements, Quality, Organization, Procurement, Cost) per PMBOK guidance. | U21: =IF(AND(OR($E21="Both",$E21=$G$9,$E21="None",$G$9="Hybrid",$G$9=""),OR($R$5="All",$R$5="",$C21=$R$5),OR($R$6="All deliverables",$R$6="",$B21="Yes")),"Show","Hide") -> Show
A22: PLN-02 | B22: Yes | C22: Governance & Management | D22: RACI | E22: Both | F22: Plan | G22: — | H22: → Close | I22: Develop Project Schedule | J22: 10 | K22: =K20 -> 46205 | L22: =WORKDAY(K21,J21-1) -> 46260 | O22: ║ Parallel with PLN-01 | P22: Project Manager | Q22: Not Started | R22: 0 | U22: =IF(AND(OR($E22="Both",$E22=$G$9,$E22="None",$G$9="Hybrid",$G$9=""),OR($R$5="All",$R$5="",$C22=$R$5),OR($R$6="All deliverables",$R$6="",$B22="Yes")),"Show","Hide") -> Show
A23: PLN-03 | B23: Yes | C23: Delivery & Execution | D23: RACI | E23: Agile | F23: Plan | G23: — | H23: → Close | I23: Develop Product Vision, Initial Backlog & Sprint Roadmap | J23: 10 | K23: =K20 -> 46205 | L23: =WORKDAY(K22,J22-1) -> 46218 | O23: ║ Parallel with PLN-01 | P23: Project Manager, Scrum Master | Q23: Not Started | R23: 0 | U23: =IF(AND(OR($E23="Both",$E23=$G$9,$E23="None",$G$9="Hybrid",$G$9=""),OR($R$5="All",$R$5="",$C23=$R$5),OR($R$6="All deliverables",$R$6="",$B23="Yes")),"Show","Hide") -> Hide
A24: PLN-04 | B24: Yes | C24: Delivery & Execution | D24: PMI | E24: Waterfall | F24: Plan | G24: — | H24: → Sec Analysis | I24: Gather and Document Requirements | J24: 30 | K24: =K20 -> 46205 | L24: =WORKDAY(K23,J23-1) -> 46218 | O24: ║ Parallel with PLN-01 | P24: Business Analyst | Q24: Not Started | R24: 0 | S24: PMBOK standard. Customer/Business accountable; BA executes. Feeds RTM, SAD, test cases. | U24: =IF(AND(OR($E24="Both",$E24=$G$9,$E24="None",$G$9="Hybrid",$G$9=""),OR($R$5="All",$R$5="",$C24=$R$5),OR($R$6="All deliverables",$R$6="",$B24="Yes")),"Show","Hide") -> Show
A25: PLN-05 | B25: Yes | C25: Delivery & Execution | D25: PMI | E25: Waterfall | F25: Plan | G25: — | H25: → Test | I25: Develop Test Plan & Test Cases | J25: 10 | K25: =K20 -> 46205 | L25: =WORKDAY(K24,J24-1) -> 46246 | O25: ║ Parallel with PLN-01 | P25: Enterprise Testing Office Lead | Q25: Not Started | R25: 0 | S25: PMBOK standard. ETO Lead owned. | U25: =IF(AND(OR($E25="Both",$E25=$G$9,$E25="None",$G$9="Hybrid",$G$9=""),OR($R$5="All",$R$5="",$C25=$R$5),OR($R$6="All deliverables",$R$6="",$B25="Yes")),"Show","Hide") -> Show
A26: PLN-06 | B26: Yes | C26: Delivery & Execution | D26: PMI | E26: Both | F26: Plan | G26: — | H26: → Test | I26: Build Requirements Traceability Matrix (RTM) | J26: 20 | K26: =K20 -> 46205 | L26: =WORKDAY(K25,J25-1) -> 46218 | O26: ║ Parallel with PLN-01 | P26: Dev Team Lead, Business Analyst | Q26: Not Started | R26: 0 | S26: PMBOK standard. IT-owned; maintained continuously — initial 20 days, ongoing updates. | U26: =IF(AND(OR($E26="Both",$E26=$G$9,$E26="None",$G$9="Hybrid",$G$9=""),OR($R$5="All",$R$5="",$C26=$R$5),OR($R$6="All deliverables",$R$6="",$B26="Yes")),"Show","Hide") -> Show
A27: PLN-07 | B27: Yes | C27: Delivery & Execution | D27: RACI | E27: Both | F27: Plan | G27: — | H27: → Design | I27: Develop EA-Level Architecture Models and Diagrams | J27: 15 | K27: =K20 -> 46205 | L27: =WORKDAY(K26,J26-1) -> 46232 | O27: ║ Parallel with PLN-01 | P27: Enterprise Architecture Lead | Q27: Not Started | R27: 0 | U27: =IF(AND(OR($E27="Both",$E27=$G$9,$E27="None",$G$9="Hybrid",$G$9=""),OR($R$5="All",$R$5="",$C27=$R$5),OR($R$6="All deliverables",$R$6="",$B27="Yes")),"Show","Hide") -> Show
A28: PLN-08 | B28: Yes | C28: Governance & Management | D28: PMI | E28: Both | F28: Plan | G28: — | H28: → Implement | I28: Develop Implementation Plan | J28: 15 | K28: =K20 -> 46205 | L28: =WORKDAY(K27,J27-1) -> 46225 | O28: ║ Parallel with PLN-01 | P28: Change and Release Manager | Q28: Not Started | R28: 0 | S28: PMBOK transition deliverable. Pairs with Rollback Plan and Go-Live Readiness Plan. | U28: =IF(AND(OR($E28="Both",$E28=$G$9,$E28="None",$G$9="Hybrid",$G$9=""),OR($R$5="All",$R$5="",$C28=$R$5),OR($R$6="All deliverables",$R$6="",$B28="Yes")),"Show","Hide") -> Show
A29: PLN-09 | B29: Yes | C29: Governance & Management | D29: PMI | E29: Both | F29: Plan | G29: — | H29: → Implement | I29: Develop Rollback Plan | J29: 10 | K29: =K20 -> 46205 | L29: =WORKDAY(K28,J28-1) -> 46225 | O29: ║ Parallel with PLN-01 | P29: Dev Team Lead, Change and Release Manager | Q29: Not Started | R29: 0 | S29: PMBOK risk-management deliverable. Gates go-live approval. | U29: =IF(AND(OR($E29="Both",$E29=$G$9,$E29="None",$G$9="Hybrid",$G$9=""),OR($R$5="All",$R$5="",$C29=$R$5),OR($R$6="All deliverables",$R$6="",$B29="Yes")),"Show","Hide") -> Show
A30: PLN-10 | B30: Yes | C30: Delivery & Execution | D30: PMI | E30: Both | F30: Plan | G30: — | H30: → Implement | I30: Develop OCM Training Plan & Materials | J30: 20 | K30: =K20 -> 46205 | L30: =WORKDAY(K29,J29-1) -> 46218 | O30: ║ Parallel with PLN-01 | P30: Organizational Change Manager | Q30: Not Started | R30: 0 | S30: PMBOK standard. Org Change Manager drives. Pairs with Transition Plan. | U30: =IF(AND(OR($E30="Both",$E30=$G$9,$E30="None",$G$9="Hybrid",$G$9=""),OR($R$5="All",$R$5="",$C30=$R$5),OR($R$6="All deliverables",$R$6="",$B30="Yes")),"Show","Hide") -> Show
A31: PLN-11 | B31: Yes | C31: Governance & Management | D31: RACI | E31: Both | F31: Plan | G31: — | H31: → Implement | I31: Develop Transition Plan | J31: 10 | K31: =K20 -> 46205 | L31: =WORKDAY(K30,J30-1) -> 46232 | O31: ║ Parallel with PLN-01 | P31: Project Manager | Q31: Not Started | R31: 0 | U31: =IF(AND(OR($E31="Both",$E31=$G$9,$E31="None",$G$9="Hybrid",$G$9=""),OR($R$5="All",$R$5="",$C31=$R$5),OR($R$6="All deliverables",$R$6="",$B31="Yes")),"Show","Hide") -> Show
A32: EXE-20 | B32: Yes | C32: Delivery & Execution | D32: RACI | E32: Agile | F32: Execute | G32: Ongoing | H32: → Close | I32: Maintain Product Backlog, Sprint Backlog, Increment & Burndown Artifacts | J32: 160 | K32: =WORKDAY(MAX(L20:L30),1) -> 46261 | L32: =WORKDAY(K31,J31-1) -> 46218 | O32: ▶ After Plan | P32: Project Manager, Scrum Master | Q32: Not Started | R32: 0 | U32: =IF(AND(OR($E32="Both",$E32=$G$9,$E32="None",$G$9="Hybrid",$G$9=""),OR($R$5="All",$R$5="",$C32=$R$5),OR($R$6="All deliverables",$R$6="",$B32="Yes")),"Show","Hide") -> Hide
A33: EXE-21 | B33: Yes | C33: Governance & Management | D33: RACI | E33: Both | F33: Execute | G33: Ongoing | H33: → Close | I33: Produce Status Reports | J33: 160 | K33: =K31 -> 46205 | L33: =WORKDAY(K32,J32-1) -> 46484 | O33: ║ Parallel with EXE-19 | P33: Project Manager | Q33: Not Started | R33: 0 | U33: =IF(AND(OR($E33="Both",$E33=$G$9,$E33="None",$G$9="Hybrid",$G$9=""),OR($R$5="All",$R$5="",$C33=$R$5),OR($R$6="All deliverables",$R$6="",$B33="Yes")),"Show","Hide") -> Show
A34: EXE-01 | B34: Yes | C34: Governance & Management | D34: Secure-by-Design | E34: Both | F34: Execute | G34: Sec Analysis | H34: Sec Analysis | I34: Conduct Business Impact Analysis (BIA) | J34: 10 | K34: =WORKDAY(MAX(L20:L30),1) -> 46261 | L34: =WORKDAY(K33,J33-1) -> 46428 | O34: ▶ After Plan | P34: Project Manager, EDD Business Owner(s) | Q34: Not Started | R34: 0 | S34: ISD/ESG/BCOSS (Andrew Mock) advisory. No duration in guide — placeholder. | U34: =IF(AND(OR($E34="Both",$E34=$G$9,$E34="None",$G$9="Hybrid",$G$9=""),OR($R$5="All",$R$5="",$C34=$R$5),OR($R$6="All deliverables",$R$6="",$B34="Yes")),"Show","Hide") -> Show
A35: EXE-02 | B35: Yes | C35: Delivery & Execution | D35: Secure-by-Design | E35: Both | F35: Execute | G35: Sec Analysis | H35: Sec Analysis | I35: Conduct Detailed Privacy Impact Analysis (PIA) | J35: 30 | K35: =K33 -> 46205 | L35: =WORKDAY(K34,J34-1) -> 46274 | O35: ║ Parallel with EXE-01 | P35: IT System Owner | Q35: Not Started | R35: 0 | S35: Guide: 30 days. CSD Privacy & Disclosure (Annette Wolfgang) advisory. | U35: =IF(AND(OR($E35="Both",$E35=$G$9,$E35="None",$G$9="Hybrid",$G$9=""),OR($R$5="All",$R$5="",$C35=$R$5),OR($R$6="All deliverables",$R$6="",$B35="Yes")),"Show","Hide") -> Show
A36: EXE-03 | B36: Yes | C36: Governance & Management | D36: Secure-by-Design | E36: Both | F36: Execute | G36: Sec Analysis | H36: Sec Analysis | I36: Perform Risk Assessment (RA) | J36: 15 | K36: =K33 -> 46205 | L36: =WORKDAY(K35,J35-1) -> 46246 | O36: ║ Parallel with EXE-01 | P36: CSD Security Lead | Q36: Not Started | R36: 0 | S36: Guide: 10–15 days; using upper bound. Legal participation required (no dedicated RACI role). | U36: =IF(AND(OR($E36="Both",$E36=$G$9,$E36="None",$G$9="Hybrid",$G$9=""),OR($R$5="All",$R$5="",$C36=$R$5),OR($R$6="All deliverables",$R$6="",$B36="Yes")),"Show","Hide") -> Show
A37: EXE-04 | B37: Yes | C37: Delivery & Execution | D37: Secure-by-Design | E37: Both | F37: Execute | G37: Sec Analysis | H37: Sec Analysis | I37: Draft System Security Plan (SSP) — Sections 1 & 2 | J37: 45 | K37: =K33 -> 46205 | L37: =WORKDAY(K36,J36-1) -> 46225 | O37: ║ Parallel with EXE-01 | P37: IT System Owner | Q37: Not Started | R37: 0 | S37: Guide: 30–45 days non-SaaS / 20 days SaaS. Using non-SaaS upper bound. | U37: =IF(AND(OR($E37="Both",$E37=$G$9,$E37="None",$G$9="Hybrid",$G$9=""),OR($R$5="All",$R$5="",$C37=$R$5),OR($R$6="All deliverables",$R$6="",$B37="Yes")),"Show","Hide") -> Show
A38: EXE-05 | B38: Yes | C38: Delivery & Execution | D38: RACI | E38: Both | F38: Execute | G38: Design | H38: Design | I38: Facilitate Cloud Review (If Applicable) | J38: 10 | K38: =WORKDAY(MAX(L33:L36),1) -> 46485 | L38: =WORKDAY(K37,J37-1) -> 46267 | O38: ▶ After Sec Analysis | P38: Dev Team Lead, Cloud Architecture Lead | Q38: Not Started | R38: 0 | S38: If Applicable | U38: =IF(AND(OR($E38="Both",$E38=$G$9,$E38="None",$G$9="Hybrid",$G$9=""),OR($R$5="All",$R$5="",$C38=$R$5),OR($R$6="All deliverables",$R$6="",$B38="Yes")),"Show","Hide") -> Show
A39: EXE-06 | B39: Yes | C39: Delivery & Execution | D39: RACI | E39: Both | F39: Execute | G39: Design | H39: Design | I39: Facilitate TARC Preparation | J39: 10 | K39: =K37 -> 46205 | L39: =WORKDAY(K38,J38-1) -> 46498 | O39: ║ Parallel with EXE-05 | P39: Dev Team Lead | Q39: Not Started | R39: 0 | U39: =IF(AND(OR($E39="Both",$E39=$G$9,$E39="None",$G$9="Hybrid",$G$9=""),OR($R$5="All",$R$5="",$C39=$R$5),OR($R$6="All deliverables",$R$6="",$B39="Yes")),"Show","Hide") -> Show
A40: EXE-07 | B40: Yes | C40: Delivery & Execution | D40: Secure-by-Design | E40: Both | F40: Execute | G40: Design | H40: Design | I40: Develop Solution Architecture Document (SAD) | J40: 20 | K40: =K37 -> 46205 | L40: =WORKDAY(K39,J39-1) -> 46218 | O40: ║ Parallel with EXE-05 | P40: Enterprise Architecture Lead, Dev Team Lead | Q40: Not Started | R40: 0 | S40: Merged with RACI "Define the Solution Architecture" per PMI consolidation — one architecture deliverable, not two. Performed by EAO. | U40: =IF(AND(OR($E40="Both",$E40=$G$9,$E40="None",$G$9="Hybrid",$G$9=""),OR($R$5="All",$R$5="",$C40=$R$5),OR($R$6="All deliverables",$R$6="",$B40="Yes")),"Show","Hide") -> Show
A41: EXE-08 | B41: Yes | C41: Delivery & Execution | D41: Secure-by-Design | E41: Both | F41: Execute | G41: Design | H41: → Implement | I41: Review and Update SSP; Begin Section 3 | J41: 10 | K41: =K37 -> 46205 | L41: =WORKDAY(K40,J40-1) -> 46232 | O41: ║ Parallel with EXE-05 | P41: Project Manager, IT System Owner | Q41: Not Started | R41: 0 | S41: Guide notes no additional time beyond meetings — placeholder for control selection workshops. | U41: =IF(AND(OR($E41="Both",$E41=$G$9,$E41="None",$G$9="Hybrid",$G$9=""),OR($R$5="All",$R$5="",$C41=$R$5),OR($R$6="All deliverables",$R$6="",$B41="Yes")),"Show","Hide") -> Show
...

Sheet Phase Summary
A1: Phase Summary (CA-PMF phases — auto-calculated from Schedule sheet)
A3: Phase | B3: # Deliverables | C3: Total Effort (bus. days) | D3: Phase Start | E3: Phase End | F3: Notes | G3: Working Days | H3: Calendar Days
A4: Concept | B4: =COUNTIF(Schedule!E12:E57,A4) -> 0 | C4: =SUMIF(Schedule!E12:E57,A4,Schedule!I12:I57) -> 0 | D4: =_xlfn.MINIFS(Schedule!J12:J57,Schedule!E12:E57,A4) -> 0 | E4: =_xlfn.MAXIFS(Schedule!K12:K57,Schedule!E12:E57,A4) -> 0 | F4: RFC Proposal — gates entry to CA-PMF. | G4: =IF(COUNT(D4:E4)=2,NETWORKDAYS(D4,E4),"") -> 0 | H4: =IF(COUNT(D4:E4)=2,E4-D4+1,"") -> 1
A5: Initiate | B5: =COUNTIF(Schedule!E12:E57,A5) -> 0 | C5: =SUMIF(Schedule!E12:E57,A5,Schedule!I12:I57) -> 0 | D5: =_xlfn.MINIFS(Schedule!J12:J57,Schedule!E12:E57,A5) -> 0 | E5: =_xlfn.MAXIFS(Schedule!K12:K57,Schedule!E12:E57,A5) -> 0 | F5: Charter, Governance, Stakeholder Register, RACI, CRAID Log, security kick-offs. | G5: =IF(COUNT(D5:E5)=2,NETWORKDAYS(D5,E5),"") -> 0 | H5: =IF(COUNT(D5:E5)=2,E5-D5+1,"") -> 1
A6: Plan | B6: =COUNTIF(Schedule!E12:E57,A6) -> 0 | C6: =SUMIF(Schedule!E12:E57,A6,Schedule!I12:I57) -> 0 | D6: =_xlfn.MINIFS(Schedule!J12:J57,Schedule!E12:E57,A6) -> 0 | E6: =_xlfn.MAXIFS(Schedule!K12:K57,Schedule!E12:E57,A6) -> 0 | F6: PMP, Schedule, Requirements Doc, RTM, Test Plan, Training Plan, Implementation/Rollback/Transition Plans, EA Models. | G6: =IF(COUNT(D6:E6)=2,NETWORKDAYS(D6,E6),"") -> 0 | H6: =IF(COUNT(D6:E6)=2,E6-D6+1,"") -> 1
A7: Execute | B7: =COUNTIF(Schedule!E12:E57,A7) -> 0 | C7: =SUMIF(Schedule!E12:E57,A7,Schedule!I12:I57) -> 0 | D7: =_xlfn.MINIFS(Schedule!J12:J57,Schedule!E12:E57,A7) -> 0 | E7: =_xlfn.MAXIFS(Schedule!K12:K57,Schedule!E12:E57,A7) -> 0 | F7: Stages sequence: Sec Analysis → Design → Test → Implement. Ongoing runs throughout. | G7: =IF(COUNT(D7:E7)=2,NETWORKDAYS(D7,E7),"") -> 0 | H7: =IF(COUNT(D7:E7)=2,E7-D7+1,"") -> 1
A8: Close | B8: =COUNTIF(Schedule!E12:E57,A8) -> 0 | C8: =SUMIF(Schedule!E12:E57,A8,Schedule!I12:I57) -> 0 | D8: =_xlfn.MINIFS(Schedule!J12:J57,Schedule!E12:E57,A8) -> 0 | E8: =_xlfn.MAXIFS(Schedule!K12:K57,Schedule!E12:E57,A8) -> 0 | F8: Lessons Learned, Closeout, EA Repo, PIR. | G8: =IF(COUNT(D8:E8)=2,NETWORKDAYS(D8,E8),"") -> 0 | H8: =IF(COUNT(D8:E8)=2,E8-D8+1,"") -> 1
A9: TOTAL EFFORT | B9: =SUM(B4:B8) -> 0 | C9: =SUM(C4:C8) -> 0 | D9: =MIN(D4:D8) -> 0 | E9: =MAX(E4:E8) -> 0 | F9: Effort = sum of deliverable days. Calendar span below = real schedule length.
A10: CALENDAR SPAN (real elapsed) | C10: =NETWORKDAYS(D10, E10) -> 0 | D10: =MIN(D4:D8) -> 0 | E10: =MAX(E4:E8) -> 0 | F10: Real project length in business days (parallel-aware). | G10: =NETWORKDAYS(D10,E10) -> 0 | H10: =E10-D10+1 -> 1
A13: By Methodology
A14: Methodology | B14: # Deliverables | C14: Total Effort | D14: First Start | E14: Last End | F14: Notes
A15: Agile | B15: =COUNTIF(Schedule!D12:D57,A15) -> 0 | C15: =SUMIF(Schedule!D12:D57,A15,Schedule!I12:I57) -> 0 | D15: =_xlfn.MINIFS(Schedule!J12:J57,Schedule!D12:D57,A15) -> 0 | E15: =_xlfn.MAXIFS(Schedule!K12:K57,Schedule!D12:D57,A15) -> 0 | F15: Agile-only artifacts (Product Backlog, Sprint Backlog). Skip these for Waterfall projects.
A16: Waterfall | B16: =COUNTIF(Schedule!D12:D57,A16) -> 0 | C16: =SUMIF(Schedule!D12:D57,A16,Schedule!I12:I57) -> 0 | D16: =_xlfn.MINIFS(Schedule!J12:J57,Schedule!D12:D57,A16) -> 0 | E16: =_xlfn.MAXIFS(Schedule!K12:K57,Schedule!D12:D57,A16) -> 0 | F16: Waterfall-only artifacts (formal Requirements Doc, Test Plan). Skip these for Agile projects (substitutes are in Product Backlog).
A17: Both | B17: =COUNTIF(Schedule!D12:D57,A17) -> 0 | C17: =SUMIF(Schedule!D12:D57,A17,Schedule!I12:I57) -> 0 | D17: =_xlfn.MINIFS(Schedule!J12:J57,Schedule!D12:D57,A17) -> 0 | E17: =_xlfn.MAXIFS(Schedule!K12:K57,Schedule!D12:D57,A17) -> 0 | F17: Method-agnostic — included regardless of delivery approach.
A20: By Source
A21: Source | B21: # Deliverables | C21: Total Effort | D21: First Start | E21: Last End | F21: Notes
A22: RACI | B22: =COUNTIF(Schedule!C12:C57,A22) -> 0 | C22: =SUMIF(Schedule!C12:C57,A22,Schedule!I12:I57) -> 0 | D22: =_xlfn.MINIFS(Schedule!J12:J57,Schedule!C12:C57,A22) -> 0 | E22: =_xlfn.MAXIFS(Schedule!K12:K57,Schedule!C12:C57,A22) -> 0 | F22: EDD PM RACI Matrix — Mar 4 (25 deliverables after consolidations).
A23: Secure-by-Design | B23: =COUNTIF(Schedule!C12:C57,A23) -> 0 | C23: =SUMIF(Schedule!C12:C57,A23,Schedule!I12:I57) -> 0 | D23: =_xlfn.MINIFS(Schedule!J12:J57,Schedule!C12:C57,A23) -> 0 | E23: =_xlfn.MAXIFS(Schedule!K12:K57,Schedule!C12:C57,A23) -> 0 | F23: Cybersecurity PM Deliverables guide (11 deliverables after SAD merge).
A24: PMI | B24: =COUNTIF(Schedule!C12:C57,A24) -> 0 | C24: =SUMIF(Schedule!C12:C57,A24,Schedule!I12:I57) -> 0 | D24: =_xlfn.MINIFS(Schedule!J12:J57,Schedule!C12:C57,A24) -> 0 | E24: =_xlfn.MAXIFS(Schedule!K12:K57,Schedule!C12:C57,A24) -> 0 | F24: PMI/PMBOK standards (7 deliverables: PMP, Governance, CRAID, Implementation, Rollback, Test Plan, Req Doc, RTM, UAT, Training, PIR).

Sheet Contacts
A1: EDD Cybersecurity Support Groups & Contacts
A3: Support Group | B3: Mailbox / Contact | C3: Scope
A4: ITB Enterprise Storage Services Group (ISD / ESG / BCOSS) | B4: edditbenterprisestorageservicesgroup@edd.ca.gov | C4: BIA, ISRP — Andrew Mock guidance.
A5: ITB CSD Privacy Oversight Team | B5: itbcsdprivacyoversightteam@edd.ca.gov | C5: PIA — Annette Wolfgang guidance.
A6: ITB CSD Security Risk and Integrated Risk Management Team | B6: itbcsdsecurityriskandintegratedriskmanagementteam@edd.ca.gov | C6: RA, SSP §1-2 & §3, PenTesting, C&A Package.
A7: ITB CSD Security Policy and Compliance Team | B7: itbcsdsecuritypolicyandcomplianceteam@edd.ca.gov | C7: SSP review/update, control compliance.
A8: ITB TGD Enterprise Architecture Office (EAO) | B8: edditbtgdenterprisearchitectureoffice@edd.ca.gov | C8: SAD review.
A9: Cybersecurity Operations and Fraud Group | B9: (Coordinate via Service Manager — Child RFC) | C9: SIEM integration for security/audit logs.
A10: Cyber Defense and Response Group (CDRG) | B10: cyberdefenseandresponsegroup@edd.ca.gov | C10: Vulnerability tooling: Nessus, Veracode, Prisma Cloud.
